Workbook

Sheet Crowdfunding
A1: id | B1: name | C1: blurb | D1: goal | E1: pledged | F1: percent_funded | G1: outcome | H1: backers_count | I1: average_donation | J1: country | K1: currency | L1: launched_at | M1: deadline | N1: date_created | O1: date_ended | P1: weekday_created | Q1: duration | R1: staff_pick | S1: spotlight | T1: category_and_subcategory | U1: primary_category | V1: subcategory
A2: 0 | B2: Baldwin, Riley and Jackson | C2: Pre-emptive tertiary standardization | D2: 100 | E2: 0 | F2: =E2/D2 -> 0 | G2: failed | H2: 0 | I2: =IF(H2<>0,E2/H2,0) -> 0 | J2: CA | K2: CAD | L2: 1448690400 | M2: 1450159200 | N2: =(((L2/60)/60)/24)+DATE(1970,1,1) -> 42336.25 | O2: =(((M2/60)/60)/24)+DATE(1970,1,1) -> 42353.25 | P2: =TEXT(CrowdfundingTable[[#This Row],[date_created]],"ddd") -> Sat | Q2: =_xlfn.DAYS(CrowdfundingTable[[#This Row],[date_ended]],CrowdfundingTable[[#This Row],[date_created]]) -> 17 | R2: FALSE | S2: FALSE | T2: food/food trucks | U2: food | V2: food trucks
A3: 1 | B3: Odom Inc | C3: Managed bottom-line architecture | D3: 1400 | E3: 14560 | F3: =E3/D3 -> 10.4 | G3: successful | H3: 158 | I3: =IF(H3<>0,E3/H3,0) -> 92.151899 | J3: US | K3: USD | L3: 1408424400 | M3: 1408597200 | N3: =(((L3/60)/60)/24)+DATE(1970,1,1) -> 41870.208 | O3: =(((M3/60)/60)/24)+DATE(1970,1,1) -> 41872.208 | P3: =TEXT(CrowdfundingTable[[#This Row],[date_created]],"ddd") -> Tue | Q3: =_xlfn.DAYS(CrowdfundingTable[[#This Row],[date_ended]],CrowdfundingTable[[#This Row],[date_created]]) -> 2 | R3: FALSE | S3: TRUE | T3: music/rock | U3: music | V3: rock
A4: 2 | B4: Melton, Robinson and Fritz | C4: Function-based leadingedge pricing structure | D4: 108400 | E4: 142523 | F4: 1.31 | G4: successful | H4: 1425 | I4: =IF(H4<>0,E4/H4,0) -> 100.01614 | J4: AU | K4: AUD | L4: 1384668000 | M4: 1384840800 | N4: =(((L4/60)/60)/24)+DATE(1970,1,1) -> 41595.25 | O4: =(((M4/60)/60)/24)+DATE(1970,1,1) -> 41597.25 | P4: =TEXT(CrowdfundingTable[[#This Row],[date_created]],"ddd") -> Sun | Q4: =_xlfn.DAYS(CrowdfundingTable[[#This Row],[date_ended]],CrowdfundingTable[[#This Row],[date_created]]) -> 2 | R4: FALSE | S4: FALSE | T4: technology/web | U4: technology | V4: web
A5: 3 | B5: Mcdonald, Gonzalez and Ross | C5: Vision-oriented fresh-thinking conglomeration | D5: 4200 | E5: 2477 | F5: =E5/D5 -> 0.5897619 | G5: failed | H5: 24 | I5: =IF(H5<>0,E5/H5,0) -> 103.20833 | J5: US | K5: USD | L5: 1565499600 | M5: 1568955600 | N5: =(((L5/60)/60)/24)+DATE(1970,1,1) -> 43688.208 | O5: =(((M5/60)/60)/24)+DATE(1970,1,1) -> 43728.208 | P5: =TEXT(CrowdfundingTable[[#This Row],[date_created]],"ddd") -> Sun | Q5: =_xlfn.DAYS(CrowdfundingTable[[#This Row],[date_ended]],CrowdfundingTable[[#This Row],[date_created]]) -> 40 | R5: FALSE | S5: FALSE | T5: music/rock | U5: music | V5: rock
A6: 4 | B6: Larson-Little | C6: Proactive foreground core | D6: 7600 | E6: 5265 | F6: =E6/D6 -> 0.69276316 | G6: failed | H6: 53 | I6: =IF(H6<>0,E6/H6,0) -> 99.339623 | J6: US | K6: USD | L6: 1547964000 | M6: 1548309600 | N6: =(((L6/60)/60)/24)+DATE(1970,1,1) -> 43485.25 | O6: =(((M6/60)/60)/24)+DATE(1970,1,1) -> 43489.25 | P6: =TEXT(CrowdfundingTable[[#This Row],[date_created]],"ddd") -> Sun | Q6: =_xlfn.DAYS(CrowdfundingTable[[#This Row],[date_ended]],CrowdfundingTable[[#This Row],[date_created]]) -> 4 | R6: FALSE | S6: FALSE | T6: theater/plays | U6: theater | V6: plays
A7: 5 | B7: Harris Group | C7: Open-source optimizing database | D7: 7600 | E7: 13195 | F7: =E7/D7 -> 1.7361842 | G7: successful | H7: 174 | I7: =IF(H7<>0,E7/H7,0) -> 75.833333 | J7: DK | K7: DKK | L7: 1346130000 | M7: 1347080400 | N7: =(((L7/60)/60)/24)+DATE(1970,1,1) -> 41149.208 | O7: =(((M7/60)/60)/24)+DATE(1970,1,1) -> 41160.208 | P7: =TEXT(CrowdfundingTable[[#This Row],[date_created]],"ddd") -> Tue | Q7: =_xlfn.DAYS(CrowdfundingTable[[#This Row],[date_ended]],CrowdfundingTable[[#This Row],[date_created]]) -> 11 | R7: FALSE | S7: FALSE | T7: theater/plays | U7: theater | V7: plays
A8: 6 | B8: Ortiz, Coleman and Mitchell | C8: Operative upward-trending algorithm | D8: 5200 | E8: 1090 | F8: =E8/D8 -> 0.20961538 | G8: failed | H8: 18 | I8: =IF(H8<>0,E8/H8,0) -> 60.555556 | J8: GB | K8: GBP | L8: 1505278800 | M8: 1505365200 | N8: =(((L8/60)/60)/24)+DATE(1970,1,1) -> 42991.208 | O8: =(((M8/60)/60)/24)+DATE(1970,1,1) -> 42992.208 | P8: =TEXT(CrowdfundingTable[[#This Row],[date_created]],"ddd") -> Wed | Q8: =_xlfn.DAYS(CrowdfundingTable[[#This Row],[date_ended]],CrowdfundingTable[[#This Row],[date_created]]) -> 1 | R8: FALSE | S8: FALSE | T8: film & video/documentary | U8: film & video | V8: documentary
A9: 7 | B9: Carter-Guzman | C9: Centralized cohesive challenge | D9: 4500 | E9: 14741 | F9: =E9/D9 -> 3.2757778 | G9: successful | H9: 227 | I9: =IF(H9<>0,E9/H9,0) -> 64.938326 | J9: DK | K9: DKK | L9: 1439442000 | M9: 1439614800 | N9: =(((L9/60)/60)/24)+DATE(1970,1,1) -> 42229.208 | O9: =(((M9/60)/60)/24)+DATE(1970,1,1) -> 42231.208 | P9: =TEXT(CrowdfundingTable[[#This Row],[date_created]],"ddd") -> Thu | Q9: =_xlfn.DAYS(CrowdfundingTable[[#This Row],[date_ended]],CrowdfundingTable[[#This Row],[date_created]]) -> 2 | R9: FALSE | S9: FALSE | T9: theater/plays | U9: theater | V9: plays
A10: 8 | B10: Nunez-Richards | C10: Exclusive attitude-oriented intranet | D10: 110100 | E10: 21946 | F10: =E10/D10 -> 0.19932788 | G10: live | H10: 708 | I10: =IF(H10<>0,E10/H10,0) -> 30.997175 | J10: DK | K10: DKK | L10: 1281330000 | M10: 1281502800 | N10: =(((L10/60)/60)/24)+DATE(1970,1,1) -> 40399.208 | O10: =(((M10/60)/60)/24)+DATE(1970,1,1) -> 40401.208 | P10: =TEXT(CrowdfundingTable[[#This Row],[date_created]],"ddd") -> Mon | Q10: =_xlfn.DAYS(CrowdfundingTable[[#This Row],[date_ended]],CrowdfundingTable[[#This Row],[date_created]]) -> 2 | R10: FALSE | S10: FALSE | T10: theater/plays | U10: theater | V10: plays
A11: 9 | B11: Rangel, Holt and Jones | C11: Open-source fresh-thinking model | D11: 6200 | E11: 3208 | F11: =E11/D11 -> 0.51741935 | G11: failed | H11: 44 | I11: =IF(H11<>0,E11/H11,0) -> 72.909091 | J11: US | K11: USD | L11: 1379566800 | M11: 1383804000 | N11: =(((L11/60)/60)/24)+DATE(1970,1,1) -> 41536.208 | O11: =(((M11/60)/60)/24)+DATE(1970,1,1) -> 41585.25 | P11: =TEXT(CrowdfundingTable[[#This Row],[date_created]],"ddd") -> Thu | Q11: =_xlfn.DAYS(CrowdfundingTable[[#This Row],[date_ended]],CrowdfundingTable[[#This Row],[date_created]]) -> 49 | R11: FALSE | S11: FALSE | T11: music/electric music | U11: music | V11: electric music
A12: 10 | B12: Green Ltd | C12: Monitored empowering installation | D12: 5200 | E12: 13838 | F12: =E12/D12 -> 2.6611538 | G12: successful | H12: 220 | I12: =IF(H12<>0,E12/H12,0) -> 62.9 | J12: US | K12: USD | L12: 1281762000 | M12: 1285909200 | N12: =(((L12/60)/60)/24)+DATE(1970,1,1) -> 40404.208 | O12: =(((M12/60)/60)/24)+DATE(1970,1,1) -> 40452.208 | P12: =TEXT(CrowdfundingTable[[#This Row],[date_created]],"ddd") -> Sat | Q12: =_xlfn.DAYS(CrowdfundingTable[[#This Row],[date_ended]],CrowdfundingTable[[#This Row],[date_created]]) -> 48 | R12: FALSE | S12: FALSE | T12: film & video/drama | U12: film & video | V12: drama
A13: 11 | B13: Perez, Johnson and Gardner | C13: Grass-roots zero administration system engine | D13: 6300 | E13: 3030 | F13: =E13/D13 -> 0.48095238 | G13: failed | H13: 27 | I13: =IF(H13<>0,E13/H13,0) -> 112.22222 | J13: US | K13: USD | L13: 1285045200 | M13: 1285563600 | N13: =(((L13/60)/60)/24)+DATE(1970,1,1) -> 40442.208 | O13: =(((M13/60)/60)/24)+DATE(1970,1,1) -> 40448.208 | P13: =TEXT(CrowdfundingTable[[#This Row],[date_created]],"ddd") -> Tue | Q13: =_xlfn.DAYS(CrowdfundingTable[[#This Row],[date_ended]],CrowdfundingTable[[#This Row],[date_created]]) -> 6 | R13: FALSE | S13: TRUE | T13: theater/plays | U13: theater | V13: plays
A14: 12 | B14: Kim Ltd | C14: Assimilated hybrid intranet | D14: 6300 | E14: 5629 | F14: =E14/D14 -> 0.89349206 | G14: failed | H14: 55 | I14: =IF(H14<>0,E14/H14,0) -> 102.34545 | J14: US | K14: USD | L14: 1571720400 | M14: 1572411600 | N14: =(((L14/60)/60)/24)+DATE(1970,1,1) -> 43760.208 | O14: =(((M14/60)/60)/24)+DATE(1970,1,1) -> 43768.208 | P14: =TEXT(CrowdfundingTable[[#This Row],[date_created]],"ddd") -> Tue | Q14: =_xlfn.DAYS(CrowdfundingTable[[#This Row],[date_ended]],CrowdfundingTable[[#This Row],[date_created]]) -> 8 | R14: FALSE | S14: FALSE | T14: film & video/drama | U14: film & video | V14: drama
A15: 13 | B15: Walker, Taylor and Coleman | C15: Multi-tiered directional open architecture | D15: 4200 | E15: 10295 | F15: =E15/D15 -> 2.4511905 | G15: successful | H15: 98 | I15: =IF(H15<>0,E15/H15,0) -> 105.05102 | J15: US | K15: USD | L15: 1465621200 | M15: 1466658000 | N15: =(((L15/60)/60)/24)+DATE(1970,1,1) -> 42532.208 | O15: =(((M15/60)/60)/24)+DATE(1970,1,1) -> 42544.208 | P15: =TEXT(CrowdfundingTable[[#This Row],[date_created]],"ddd") -> Sat | Q15: =_xlfn.DAYS(CrowdfundingTable[[#This Row],[date_ended]],CrowdfundingTable[[#This Row],[date_created]]) -> 12 | R15: FALSE | S15: FALSE | T15: music/indie rock | U15: music | V15: indie rock
A16: 14 | B16: Rodriguez, Rose and Stewart | C16: Cloned directional synergy | D16: 28200 | E16: 18829 | F16: =E16/D16 -> 0.66769504 | G16: failed | H16: 200 | I16: =IF(H16<>0,E16/H16,0) -> 94.145 | J16: US | K16: USD | L16: 1331013600 | M16: 1333342800 | N16: =(((L16/60)/60)/24)+DATE(1970,1,1) -> 40974.25 | O16: =(((M16/60)/60)/24)+DATE(1970,1,1) -> 41001.208 | P16: =TEXT(CrowdfundingTable[[#This Row],[date_created]],"ddd") -> Tue | Q16: =_xlfn.DAYS(CrowdfundingTable[[#This Row],[date_ended]],CrowdfundingTable[[#This Row],[date_created]]) -> 27 | R16: FALSE | S16: FALSE | T16: music/indie rock | U16: music | V16: indie rock
... A1001: 999 | B1001: Hernandez, Norton and Kelley | C1001: Expanded eco-centric policy | D1001: 111100 | E1001: 62819 | F1001: =E1001/D1001 -> 0.56542754 | G1001: canceled | H1001: 1122 | I1001: =IF(H1001<>0,E1001/H1001,0) -> 55.988414 | J1001: US | K1001: USD | L1001: 1467176400 | M1001: 1467781200 | N1001: =(((L1001/60)/60)/24)+DATE(1970,1,1) -> 42550.208 | O1001: =(((M1001/60)/60)/24)+DATE(1970,1,1) -> 42557.208 | P1001: =TEXT(CrowdfundingTable[[#This Row],[date_created]],"ddd") -> Wed | Q1001: =_xlfn.DAYS(CrowdfundingTable[[#This Row],[date_ended]],CrowdfundingTable[[#This Row],[date_created]]) -> 7 | R1001: FALSE | S1001: FALSE | T1001: food/food trucks | U1001: food | V1001: food trucks

Sheet Outcomes vs. Categories
A1: country | B1: (All)
A2: Years | B2: (All)
A4: Count of outcome | B4: Column Labels
A5: Row Labels | B5: canceled | C5: failed | D5: live | E5: successful | F5: Grand Total
A6: film & video | B6: 11 | C6: 60 | D6: 5 | E6: 102 | F6: 178
A7: animation | B7: 1 | C7: 10 | D7: 2 | E7: 21 | F7: 34
A8: documentary | B8: 4 | C8: 21 | D8: 1 | E8: 34 | F8: 60
A9: drama | B9: 2 | C9: 12 | D9: 1 | E9: 22 | F9: 37
A10: science fiction | C10: 9 | E10: 5 | F10: 14
A11: shorts | B11: 1 | C11: 5 | D11: 1 | E11: 9 | F11: 16
A12: television | B12: 3 | C12: 3 | E12: 11 | F12: 17
A13: food | B13: 4 | C13: 20 | E13: 22 | F13: 46
A14: food trucks | B14: 4 | C14: 20 | E14: 22 | F14: 46
A15: games | B15: 1 | C15: 23 | D15: 3 | E15: 21 | F15: 48
A16: mobile games | C16: 8 | D16: 1 | E16: 4 | F16: 13
A17: video games | B17: 1 | C17: 15 | D17: 2 | E17: 17 | F17: 35
A18: journalism | E18: 4 | F18: 4
A19: audio | E19: 4 | F19: 4
A20: music | B20: 10 | C20: 66 | E20: 99 | F20: 175
A21: electric music | C21: 8 | E21: 10 | F21: 18
A22: indie rock | B22: 3 | C22: 19 | E22: 23 | F22: 45
A23: jazz | B23: 1 | C23: 6 | E23: 10 | F23: 17
A24: metal | C24: 3 | E24: 4 | F24: 7
A25: rock | B25: 6 | C25: 30 | E25: 49 | F25: 85
A26: world music | E26: 3 | F26: 3
A27: photography | B27: 4 | C27: 11 | D27: 1 | E27: 26 | F27: 42
A28: photography books | B28: 4 | C28: 11 | D28: 1 | E28: 26 | F28: 42
A29: publishing | B29: 2 | C29: 24 | D29: 1 | E29: 40 | F29: 67
A30: fiction | B30: 1 | C30: 7 | E30: 9 | F30: 17
A31: nonfiction | B31: 1 | C31: 6 | D31: 1 | E31: 13 | F31: 21
A32: radio & podcasts | C32: 4 | E32: 4 | F32: 8
A33: translations | C33: 7 | E33: 14 | F33: 21
A34: technology | B34: 2 | C34: 28 | D34: 2 | E34: 64 | F34: 96
A35: wearables | C35: 16 | D35: 1 | E35: 28 | F35: 45
A36: web | B36: 2 | C36: 12 | D36: 1 | E36: 36 | F36: 51
A37: theater | B37: 23 | C37: 132 | D37: 2 | E37: 187 | F37: 344
A38: plays | B38: 23 | C38: 132 | D38: 2 | E38: 187 | F38: 344
A39: Grand Total | B39: 57 | C39: 364 | D39: 14 | E39: 565 | F39: 1000

Sheet Mean Funding Ratio
A1: country | B1: (All)
A2: Years | B2: (All)
A4: Average of percent_funded | B4: Column Labels
A5: Row Labels | B5: canceled | C5: failed | D5: live | E5: successful | F5: Grand Total
A6: film & video | B6: 0.45857998 | C6: 0.51656024 | D6: 0.57172845 | E6: 3.0380113 | F6: 1.9594033
A7: animation | B7: 0.34959979 | C7: 0.44051363 | D7: 0.75119745 | E7: 3.3387929 | F7: 2.2462289
A8: documentary | B8: 0.70523298 | C8: 0.53165931 | D8: 0.21188689 | E8: 3.0038866 | F8: 1.9388301
A9: drama | B9: 0.10627538 | C9: 0.5633952 | D9: 0.56186047 | E9: 3.1334786 | F9: 2.0668022
A10: science fiction | C10: 0.39775079 | E10: 2.4974338 | F10: 1.1476376
A11: shorts | B11: 0.23995288 | C11: 0.69915253 | D11: 0.5825 | E11: 3.3460966 | F11: 2.1520678
A12: television | B12: 0.47378147 | C12: 0.52912343 | E12: 2.371981 | F12: 1.7117944
A13: food | B13: 0.50408392 | C13: 0.4962951 | E13: 3.9271729 | F13: 2.137827
A14: food trucks | B14: 0.50408392 | C14: 0.4962951 | E14: 3.9271729 | F14: 2.137827
A15: games | B15: 0.27176538 | C15: 0.51149586 | D15: 0.51516824 | E15: 4.2327345 | F15: 2.1347729
A16: mobile games | C16: 0.5194476 | D16: 0.36132726 | E16: 1.8081137 | F16: 0.90379715
A17: video games | B17: 0.27176538 | C17: 0.50725493 | D17: 0.59208873 | E17: 4.8032335 | F17: 2.5919925
A18: journalism | E18: 1.5062985 | F18: 1.5062985
A19: audio | E19: 1.5062985 | F19: 1.5062985
A20: music | B20: 0.38498633 | C20: 0.45803203 | E20: 3.2937501 | F20: 2.0580642
A21: electric music | C21: 0.37679821 | E21: 3.7954948 | F21: 2.2760741
A22: indie rock | B22: 0.30187573 | C22: 0.51243169 | E22: 2.850915 | F22: 1.6936194
A23: jazz | B23: 0.18853659 | C23: 0.29131793 | E23: 4.6720698 | F23: 2.8621848
A24: metal | C24: 0.45755732 | E24: 3.2015425 | F24: 2.0255489
A25: rock | B25: 0.45928325 | C25: 0.47863155 | E25: 3.1998112 | F25: 2.0459458
A26: world music | E26: 2.0792167 | F26: 2.0792167
A27: photography | B27: 0.61272047 | C27: 0.46863595 | D27: 0.012706571 | E27: 2.6819133 | F27: 1.8416269
A28: photography books | B28: 0.61272047 | C28: 0.46863595 | D28: 0.012706571 | E28: 2.6819133 | F28: 1.8416269
A29: publishing | B29: 0.35870274 | C29: 0.4224918 | D29: 0.017292683 | E29: 2.9800017 | F29: 1.9414115
A30: fiction | B30: 0.38844444 | C30: 0.546806 | E30: 3.3985746 | F30: 2.0472505
A31: nonfiction | B31: 0.32896104 | C31: 0.40494185 | D31: 0.017292683 | E31: 3.6593226 | F31: 2.3974809
A32: radio & podcasts | C32: 0.4006924 | E32: 1.7630795 | F32: 1.081886
A33: translations | C33: 0.32567722 | E33: 2.4278133 | F33: 1.7271013
A34: technology | B34: 0.6447619 | C34: 0.56331661 | D34: 0.60603004 | E34: 3.0988806 | F34: 2.2562792
A35: wearables | C35: 0.55778883 | D35: 0.58973684 | E35: 2.8267161 | F35: 1.9702757
A36: web | B36: 0.6447619 | C36: 0.57068697 | D36: 0.62232323 | E36: 3.3105641 | F36: 2.5086353
A37: theater | B37: 0.45757574 | C37: 0.49562153 | D37: 0.31396353 | E37: 3.1446431 | F37: 1.932042
A38: plays | B38: 0.45757574 | C38: 0.49562153 | D38: 0.31396353 | E38: 3.1446431 | F38: 1.932042
A39: Grand Total | B39: 0.45902452 | C39: 0.49286742 | D39: 0.44815238 | E39: 3.1726996 | F39: 2.0044175

Sheet Median Funding Ratio
A2: Row Labels | B2: canceled | C2: failed | D2: live | E2: successful | F2: Grand Total
A3: film & video | B3: {=IFERROR(ROUND(MEDIAN(_xlfn._xlws.FILTER(CrowdfundingTable[percent_funded],(CrowdfundingTable[primary_category]=$A3)*(CrowdfundingTable[outcome]=$B$2))),2),"")} -> 0.39 | C3: {=IFERROR(ROUND(MEDIAN(_xlfn._xlws.FILTER(CrowdfundingTable[percent_funded],(CrowdfundingTable[primary_category]=$A3)*(CrowdfundingTable[outcome]=$C$2))),2),"")} -> 0.52 | D3: {=IFERROR(ROUND(MEDIAN(_xlfn._xlws.FILTER(CrowdfundingTable[percent_funded],(CrowdfundingTable[primary_category]=$A3)*(CrowdfundingTable[outcome]=$D$2))),2),"")} -> 0.58 | E3: {=IFERROR(ROUND(MEDIAN(_xlfn._xlws.FILTER(CrowdfundingTable[percent_funded],(CrowdfundingTable[primary_category]=$A3)*(CrowdfundingTable[outcome]=$E$2))),2),"")} -> 2.07 | F3: {=IFERROR(ROUND(MEDIAN(_xlfn._xlws.FILTER(CrowdfundingTable[percent_funded],CrowdfundingTable[primary_category]=$A3)),2),"")} -> 1.23
A4: animation | B4: {=IFERROR(ROUND(MEDIAN(_xlfn._xlws.FILTER(CrowdfundingTable[percent_funded],(CrowdfundingTable[subcategory]=$A4)*(CrowdfundingTable[outcome]=$B$2))),2),"")} -> 0.35 | C4: {=IFERROR(ROUND(MEDIAN(_xlfn._xlws.FILTER(CrowdfundingTable[percent_funded],(CrowdfundingTable[subcategory]=$A4)*(CrowdfundingTable[outcome]=$C$2))),2),"")} -> 0.46 | D4: {=IFERROR(ROUND(MEDIAN(_xlfn._xlws.FILTER(CrowdfundingTable[percent_funded],(CrowdfundingTable[subcategory]=$A4)*(CrowdfundingTable[outcome]=$D$2))),2),"")} -> 0.75 | E4: {=IFERROR(ROUND(MEDIAN(_xlfn._xlws.FILTER(CrowdfundingTable[percent_funded],(CrowdfundingTable[subcategory]=$A4)*(CrowdfundingTable[outcome]=$E$2))),2),"")} -> 1.93 | F4: {=IFERROR(ROUND(MEDIAN(_xlfn._xlws.FILTER(CrowdfundingTable[percent_funded],CrowdfundingTable[subcategory]=$A4)),2),"")} -> 1.39
A5: documentary | B5: {=IFERROR(ROUND(MEDIAN(_xlfn._xlws.FILTER(CrowdfundingTable[percent_funded],(CrowdfundingTable[subcategory]=$A5)*(CrowdfundingTable[outcome]=$B$2))),2),"")} -> 0.67 | C5: {=IFERROR(ROUND(MEDIAN(_xlfn._xlws.FILTER(CrowdfundingTable[percent_funded],(CrowdfundingTable[subcategory]=$A5)*(CrowdfundingTable[outcome]=$C$2))),2),"")} -> 0.54 | D5: {=IFERROR(ROUND(MEDIAN(_xlfn._xlws.FILTER(CrowdfundingTable[percent_funded],(CrowdfundingTable[subcategory]=$A5)*(CrowdfundingTable[outcome]=$D$2))),2),"")} -> 0.21 | E5: {=IFERROR(ROUND(MEDIAN(_xlfn._xlws.FILTER(CrowdfundingTable[percent_funded],(CrowdfundingTable[subcategory]=$A5)*(CrowdfundingTable[outcome]=$E$2))),2),"")} -> 2.03 | F5: {=IFERROR(ROUND(MEDIAN(_xlfn._xlws.FILTER(CrowdfundingTable[percent_funded],CrowdfundingTable[subcategory]=$A5)),2),"")} -> 1.26
A6: drama | B6: {=IFERROR(ROUND(MEDIAN(_xlfn._xlws.FILTER(CrowdfundingTable[percent_funded],(CrowdfundingTable[subcategory]=$A6)*(CrowdfundingTable[outcome]=$B$2))),2),"")} -> 0.11 | C6: {=IFERROR(ROUND(MEDIAN(_xlfn._xlws.FILTER(CrowdfundingTable[percent_funded],(CrowdfundingTable[subcategory]=$A6)*(CrowdfundingTable[outcome]=$C$2))),2),"")} -> 0.57 | D6: {=IFERROR(ROUND(MEDIAN(_xlfn._xlws.FILTER(CrowdfundingTable[percent_funded],(CrowdfundingTable[subcategory]=$A6)*(CrowdfundingTable[outcome]=$D$2))),2),"")} -> 0.56 | E6: {=IFERROR(ROUND(MEDIAN(_xlfn._xlws.FILTER(CrowdfundingTable[percent_funded],(CrowdfundingTable[subcategory]=$A6)*(CrowdfundingTable[outcome]=$E$2))),2),"")} -> 1.82 | F6: {=IFERROR(ROUND(MEDIAN(_xlfn._xlws.FILTER(CrowdfundingTable[percent_funded],CrowdfundingTable[subcategory]=$A6)),2),"")} -> 1.4
A7: science fiction | B7: {=IFERROR(ROUND(MEDIAN(_xlfn._xlws.FILTER(CrowdfundingTable[percent_funded],(CrowdfundingTable[subcategory]=$A7)*(CrowdfundingTable[outcome]=$B$2))),2),"")} | C7: {=IFERROR(ROUND(MEDIAN(_xlfn._xlws.FILTER(CrowdfundingTable[percent_funded],(CrowdfundingTable[subcategory]=$A7)*(CrowdfundingTable[outcome]=$C$2))),2),"")} -> 0.45 | D7: {=IFERROR(ROUND(MEDIAN(_xlfn._xlws.FILTER(CrowdfundingTable[percent_funded],(CrowdfundingTable[subcategory]=$A7)*(CrowdfundingTable[outcome]=$D$2))),2),"")} | E7: {=IFERROR(ROUND(MEDIAN(_xlfn._xlws.FILTER(CrowdfundingTable[percent_funded],(CrowdfundingTable[subcategory]=$A7)*(CrowdfundingTable[outcome]=$E$2))),2),"")} -> 1.99 | F7: {=IFERROR(ROUND(MEDIAN(_xlfn._xlws.FILTER(CrowdfundingTable[percent_funded],CrowdfundingTable[subcategory]=$A7)),2),"")} -> 0.58
A8: shorts | B8: {=IFERROR(ROUND(MEDIAN(_xlfn._xlws.FILTER(CrowdfundingTable[percent_funded],(CrowdfundingTable[subcategory]=$A8)*(CrowdfundingTable[outcome]=$B$2))),2),"")} -> 0.24 | C8: {=IFERROR(ROUND(MEDIAN(_xlfn._xlws.FILTER(CrowdfundingTable[percent_funded],(CrowdfundingTable[subcategory]=$A8)*(CrowdfundingTable[outcome]=$C$2))),2),"")} -> 0.88 | D8: {=IFERROR(ROUND(MEDIAN(_xlfn._xlws.FILTER(CrowdfundingTable[percent_funded],(CrowdfundingTable[subcategory]=$A8)*(CrowdfundingTable[outcome]=$D$2))),2),"")} -> 0.58 | E8: {=IFERROR(ROUND(MEDIAN(_xlfn._xlws.FILTER(CrowdfundingTable[percent_funded],(CrowdfundingTable[subcategory]=$A8)*(CrowdfundingTable[outcome]=$E$2))),2),"")} -> 3.29 | F8: {=IFERROR(ROUND(MEDIAN(_xlfn._xlws.FILTER(CrowdfundingTable[percent_funded],CrowdfundingTable[subcategory]=$A8)),2),"")} -> 1.78
A9: television | B9: {=IFERROR(ROUND(MEDIAN(_xlfn._xlws.FILTER(CrowdfundingTable[percent_funded],(CrowdfundingTable[subcategory]=$A9)*(CrowdfundingTable[outcome]=$B$2))),2),"")} -> 0.39 | C9: {=IFERROR(ROUND(MEDIAN(_xlfn._xlws.FILTER(CrowdfundingTable[percent_funded],(CrowdfundingTable[subcategory]=$A9)*(CrowdfundingTable[outcome]=$C$2))),2),"")} -> 0.59 | D9: {=IFERROR(ROUND(MEDIAN(_xlfn._xlws.FILTER(CrowdfundingTable[percent_funded],(CrowdfundingTable[subcategory]=$A9)*(CrowdfundingTable[outcome]=$D$2))),2),"")} | E9: {=IFERROR(ROUND(MEDIAN(_xlfn._xlws.FILTER(CrowdfundingTable[percent_funded],(CrowdfundingTable[subcategory]=$A9)*(CrowdfundingTable[outcome]=$E$2))),2),"")} -> 1.89 | F9: {=IFERROR(ROUND(MEDIAN(_xlfn._xlws.FILTER(CrowdfundingTable[percent_funded],CrowdfundingTable[subcategory]=$A9)),2),"")} -> 1.56
A10: food | B10: {=IFERROR(ROUND(MEDIAN(_xlfn._xlws.FILTER(CrowdfundingTable[percent_funded],(CrowdfundingTable[primary_category]=$A10)*(CrowdfundingTable[outcome]=$B$2))),2),"")} -> 0.6 | C10: {=IFERROR(ROUND(MEDIAN(_xlfn._xlws.FILTER(CrowdfundingTable[percent_funded],(CrowdfundingTable[primary_category]=$A10)*(CrowdfundingTable[outcome]=$C$2))),2),"")} -> 0.59 | D10: {=IFERROR(ROUND(MEDIAN(_xlfn._xlws.FILTER(CrowdfundingTable[percent_funded],(CrowdfundingTable[primary_category]=$A10)*(CrowdfundingTable[outcome]=$D$2))),2),"")} | E10: {=IFERROR(ROUND(MEDIAN(_xlfn._xlws.FILTER(CrowdfundingTable[percent_funded],(CrowdfundingTable[primary_category]=$A10)*(CrowdfundingTable[outcome]=$E$2))),2),"")} -> 3.29 | F10: {=IFERROR(ROUND(MEDIAN(_xlfn._xlws.FILTER(CrowdfundingTable[percent_funded],CrowdfundingTable[primary_category]=$A10)),2),"")} -> 0.97
A11: food trucks | B11: {=IFERROR(ROUND(MEDIAN(_xlfn._xlws.FILTER(CrowdfundingTable[percent_funded],(CrowdfundingTable[subcategory]=$A11)*(CrowdfundingTable[outcome]=$B$2))),2),"")} -> 0.6 | C11: {=IFERROR(ROUND(MEDIAN(_xlfn._xlws.FILTER(CrowdfundingTable[percent_funded],(CrowdfundingTable[subcategory]=$A11)*(CrowdfundingTable[outcome]=$C$2))),2),"")} -> 0.59 | D11: {=IFERROR(ROUND(MEDIAN(_xlfn._xlws.FILTER(CrowdfundingTable[percent_funded],(CrowdfundingTable[subcategory]=$A11)*(CrowdfundingTable[outcome]=$D$2))),2),"")} | E11: {=IFERROR(ROUND(MEDIAN(_xlfn._xlws.FILTER(CrowdfundingTable[percent_funded],(CrowdfundingTable[subcategory]=$A11)*(CrowdfundingTable[outcome]=$E$2))),2),"")} -> 3.29 | F11: {=IFERROR(ROUND(MEDIAN(_xlfn._xlws.FILTER(CrowdfundingTable[percent_funded],CrowdfundingTable[subcategory]=$A11)),2),"")} -> 0.97
A12: games | B12: {=IFERROR(ROUND(MEDIAN(_xlfn._xlws.FILTER(CrowdfundingTable[percent_funded],(CrowdfundingTable[primary_category]=$A12)*(CrowdfundingTable[outcome]=$B$2))),2),"")} -> 0.27 | C12: {=IFERROR(ROUND(MEDIAN(_xlfn._xlws.FILTER(CrowdfundingTable[percent_funded],(CrowdfundingTable[primary_category]=$A12)*(CrowdfundingTable[outcome]=$C$2))),2),"")} -> 0.5 | D12: {=IFERROR(ROUND(MEDIAN(_xlfn._xlws.FILTER(CrowdfundingTable[percent_funded],(CrowdfundingTable[primary_category]=$A12)*(CrowdfundingTable[outcome]=$D$2))),2),"")} -> 0.36 | E12: {=IFERROR(ROUND(MEDIAN(_xlfn._xlws.FILTER(CrowdfundingTable[percent_funded],(CrowdfundingTable[primary_category]=$A12)*(CrowdfundingTable[outcome]=$E$2))),2),"")} -> 2.39 | F12: {=IFERROR(ROUND(MEDIAN(_xlfn._xlws.FILTER(CrowdfundingTable[percent_funded],CrowdfundingTable[primary_category]=$A12)),2),"")} -> 0.96
A13: mobile games | B13: {=IFERROR(ROUND(MEDIAN(_xlfn._xlws.FILTER(CrowdfundingTable[percent_funded],(CrowdfundingTable[subcategory]=$A13)*(CrowdfundingTable[outcome]=$B$2))),2),"")} | C13: {=IFERROR(ROUND(MEDIAN(_xlfn._xlws.FILTER(CrowdfundingTable[percent_funded],(CrowdfundingTable[subcategory]=$A13)*(CrowdfundingTable[outcome]=$C$2))),2),"")} -> 0.44 | D13: {=IFERROR(ROUND(MEDIAN(_xlfn._xlws.FILTER(CrowdfundingTable[percent_funded],(CrowdfundingTable[subcategory]=$A13)*(CrowdfundingTable[outcome]=$D$2))),2),"")} -> 0.36 | E13: {=IFERROR(ROUND(MEDIAN(_xlfn._xlws.FILTER(CrowdfundingTable[percent_funded],(CrowdfundingTable[subcategory]=$A13)*(CrowdfundingTable[outcome]=$E$2))),2),"")} -> 1.81 | F13: {=IFERROR(ROUND(MEDIAN(_xlfn._xlws.FILTER(CrowdfundingTable[percent_funded],CrowdfundingTable[subcategory]=$A13)),2),"")} -> 0.55
A14: video games | B14: {=IFERROR(ROUND(MEDIAN(_xlfn._xlws.FILTER(CrowdfundingTable[percent_funded],(CrowdfundingTable[subcategory]=$A14)*(CrowdfundingTable[outcome]=$B$2))),2),"")} -> 0.27 | C14: {=IFERROR(ROUND(MEDIAN(_xlfn._xlws.FILTER(CrowdfundingTable[percent_funded],(CrowdfundingTable[subcategory]=$A14)*(CrowdfundingTable[outcome]=$C$2))),2),"")} -> 0.5 | D14: {=IFERROR(ROUND(MEDIAN(_xlfn._xlws.FILTER(CrowdfundingTable[percent_funded],(CrowdfundingTable[subcategory]=$A14)*(CrowdfundingTable[outcome]=$D$2))),2),"")} -> 0.59 | E14: {=IFERROR(ROUND(MEDIAN(_xlfn._xlws.FILTER(CrowdfundingTable[percent_funded],(CrowdfundingTable[subcategory]=$A14)*(CrowdfundingTable[outcome]=$E$2))),2),"")} -> 3.1 | F14: {=IFERROR(ROUND(MEDIAN(_xlfn._xlws.FILTER(CrowdfundingTable[percent_funded],CrowdfundingTable[subcategory]=$A14)),2),"")} -> 0.97
A15: journalism | B15: {=IFERROR(ROUND(MEDIAN(_xlfn._xlws.FILTER(CrowdfundingTable[percent_funded],(CrowdfundingTable[primary_category]=$A15)*(CrowdfundingTable[outcome]=$B$2))),2),"")} | C15: {=IFERROR(ROUND(MEDIAN(_xlfn._xlws.FILTER(CrowdfundingTable[percent_funded],(CrowdfundingTable[primary_category]=$A15)*(CrowdfundingTable[outcome]=$C$2))),2),"")} | D15: {=IFERROR(ROUND(MEDIAN(_xlfn._xlws.FILTER(CrowdfundingTable[percent_funded],(CrowdfundingTable[primary_category]=$A15)*(CrowdfundingTable[outcome]=$D$2))),2),"")} | E15: {=IFERROR(ROUND(MEDIAN(_xlfn._xlws.FILTER(CrowdfundingTable[percent_funded],(CrowdfundingTable[primary_category]=$A15)*(CrowdfundingTable[outcome]=$E$2))),2),"")} -> 1.5 | F15: {=IFERROR(ROUND(MEDIAN(_xlfn._xlws.FILTER(CrowdfundingTable[percent_funded],CrowdfundingTable[primary_category]=$A15)),2),"")} -> 1.5
A16: audio | B16: {=IFERROR(ROUND(MEDIAN(_xlfn._xlws.FILTER(CrowdfundingTable[percent_funded],(CrowdfundingTable[subcategory]=$A16)*(CrowdfundingTable[outcome]=$B$2))),2),"")} | C16: {=IFERROR(ROUND(MEDIAN(_xlfn._xlws.FILTER(CrowdfundingTable[percent_funded],(CrowdfundingTable[subcategory]=$A16)*(CrowdfundingTable[outcome]=$C$2))),2),"")} | D16: {=IFERROR(ROUND(MEDIAN(_xlfn._xlws.FILTER(CrowdfundingTable[percent_funded],(CrowdfundingTable[subcategory]=$A16)*(CrowdfundingTable[outcome]=$D$2))),2),"")} | E16: {=IFERROR(ROUND(MEDIAN(_xlfn._xlws.FILTER(CrowdfundingTable[percent_funded],(CrowdfundingTable[subcategory]=$A16)*(CrowdfundingTable[outcome]=$E$2))),2),"")} -> 1.5 | F16: {=IFERROR(ROUND(MEDIAN(_xlfn._xlws.FILTER(CrowdfundingTable[percent_funded],CrowdfundingTable[subcategory]=$A16)),2),"")} -> 1.5
A17: music | B17: {=IFERROR(ROUND(MEDIAN(_xlfn._xlws.FILTER(CrowdfundingTable[percent_funded],(CrowdfundingTable[primary_category]=$A17)*(CrowdfundingTable[outcome]=$B$2))),2),"")} -> 0.38 | C17: {=IFERROR(ROUND(MEDIAN(_xlfn._xlws.FILTER(CrowdfundingTable[percent_funded],(CrowdfundingTable[primary_category]=$A17)*(CrowdfundingTable[outcome]=$C$2))),2),"")} -> 0.45 | D17: {=IFERROR(ROUND(MEDIAN(_xlfn._xlws.FILTER(CrowdfundingTable[percent_funded],(CrowdfundingTable[primary_category]=$A17)*(CrowdfundingTable[outcome]=$D$2))),2),"")} | E17: {=IFERROR(ROUND(MEDIAN(_xlfn._xlws.FILTER(CrowdfundingTable[percent_funded],(CrowdfundingTable[primary_category]=$A17)*(CrowdfundingTable[outcome]=$E$2))),2),"")} -> 2.08 | F17: {=IFERROR(ROUND(MEDIAN(_xlfn._xlws.FILTER(CrowdfundingTable[percent_funded],CrowdfundingTable[primary_category]=$A17)),2),"")} -> 1.23
A18: electric music | B18: {=IFERROR(ROUND(MEDIAN(_xlfn._xlws.FILTER(CrowdfundingTable[percent_funded],(CrowdfundingTable[subcategory]=$A18)*(CrowdfundingTable[outcome]=$B$2))),2),"")} | C18: {=IFERROR(ROUND(MEDIAN(_xlfn._xlws.FILTER(CrowdfundingTable[percent_funded],(CrowdfundingTable[subcategory]=$A18)*(CrowdfundingTable[outcome]=$C$2))),2),"")} -> 0.41 | D18: {=IFERROR(ROUND(MEDIAN(_xlfn._xlws.FILTER(CrowdfundingTable[percent_funded],(CrowdfundingTable[subcategory]=$A18)*(CrowdfundingTable[outcome]=$D$2))),2),"")} | E18: {=IFERROR(ROUND(MEDIAN(_xlfn._xlws.FILTER(CrowdfundingTable[percent_funded],(CrowdfundingTable[subcategory]=$A18)*(CrowdfundingTable[outcome]=$E$2))),2),"")} -> 2.09 | F18: {=IFERROR(ROUND(MEDIAN(_xlfn._xlws.FILTER(CrowdfundingTable[percent_funded],CrowdfundingTable[subcategory]=$A18)),2),"")} -> 1.46
A19: indie rock | B19: {=IFERROR(ROUND(MEDIAN(_xlfn._xlws.FILTER(CrowdfundingTable[percent_funded],(CrowdfundingTable[subcategory]=$A19)*(CrowdfundingTable[outcome]=$B$2))),2),"")} -> 0.11 | C19: {=IFERROR(ROUND(MEDIAN(_xlfn._xlws.FILTER(CrowdfundingTable[percent_funded],(CrowdfundingTable[subcategory]=$A19)*(CrowdfundingTable[outcome]=$C$2))),2),"")} -> 0.57 | D19: {=IFERROR(ROUND(MEDIAN(_xlfn._xlws.FILTER(CrowdfundingTable[percent_funded],(CrowdfundingTable[subcategory]=$A19)*(CrowdfundingTable[outcome]=$D$2))),2),"")} | E19: {=IFERROR(ROUND(MEDIAN(_xlfn._xlws.FILTER(CrowdfundingTable[percent_funded],(CrowdfundingTable[subcategory]=$A19)*(CrowdfundingTable[outcome]=$E$2))),2),"")} -> 1.76 | F19: {=IFERROR(ROUND(MEDIAN(_xlfn._xlws.FILTER(CrowdfundingTable[percent_funded],CrowdfundingTable[subcategory]=$A19)),2),"")} -> 1.04
A20: jazz | B20: {=IFERROR(ROUND(MEDIAN(_xlfn._xlws.FILTER(CrowdfundingTable[percent_funded],(CrowdfundingTable[subcategory]=$A20)*(CrowdfundingTable[outcome]=$B$2))),2),"")} -> 0.19 | C20: {=IFERROR(ROUND(MEDIAN(_xlfn._xlws.FILTER(CrowdfundingTable[percent_funded],(CrowdfundingTable[subcategory]=$A20)*(CrowdfundingTable[outcome]=$C$2))),2),"")} -> 0.19 | D20: {=IFERROR(ROUND(MEDIAN(_xlfn._xlws.FILTER(CrowdfundingTable[percent_funded],(CrowdfundingTable[subcategory]=$A20)*(CrowdfundingTable[outcome]=$D$2))),2),"")} | E20: {=IFERROR(ROUND(MEDIAN(_xlfn._xlws.FILTER(CrowdfundingTable[percent_funded],(CrowdfundingTable[subcategory]=$A20)*(CrowdfundingTable[outcome]=$E$2))),2),"")} -> 3.46 | F20: {=IFERROR(ROUND(MEDIAN(_xlfn._xlws.FILTER(CrowdfundingTable[percent_funded],CrowdfundingTable[subcategory]=$A20)),2),"")} -> 1.77
A21: metal | B21: {=IFERROR(ROUND(MEDIAN(_xlfn._xlws.FILTER(CrowdfundingTable[percent_funded],(CrowdfundingTable[subcategory]=$A21)*(CrowdfundingTable[outcome]=$B$2))),2),"")} | C21: {=IFERROR(ROUND(MEDIAN(_xlfn._xlws.FILTER(CrowdfundingTable[percent_funded],(CrowdfundingTable[subcategory]=$A21)*(CrowdfundingTable[outcome]=$C$2))),2),"")} -> 0.37 | D21: {=IFERROR(ROUND(MEDIAN(_xlfn._xlws.FILTER(CrowdfundingTable[percent_funded],(CrowdfundingTable[subcategory]=$A21)*(CrowdfundingTable[outcome]=$D$2))),2),"")} | E21: {=IFERROR(ROUND(MEDIAN(_xlfn._xlws.FILTER(CrowdfundingTable[percent_funded],(CrowdfundingTable[subcategory]=$A21)*(CrowdfundingTable[outcome]=$E$2))),2),"")} -> 3.16 | F21: {=IFERROR(ROUND(MEDIAN(_xlfn._xlws.FILTER(CrowdfundingTable[percent_funded],CrowdfundingTable[subcategory]=$A21)),2),"")} -> 1.22
A22: rock | B22: {=IFERROR(ROUND(MEDIAN(_xlfn._xlws.FILTER(CrowdfundingTable[percent_funded],(CrowdfundingTable[subcategory]=$A22)*(CrowdfundingTable[outcome]=$B$2))),2),"")} -> 0.57 | C22: {=IFERROR(ROUND(MEDIAN(_xlfn._xlws.FILTER(CrowdfundingTable[percent_funded],(CrowdfundingTable[subcategory]=$A22)*(CrowdfundingTable[outcome]=$C$2))),2),"")} -> 0.45 | D22: {=IFERROR(ROUND(MEDIAN(_xlfn._xlws.FILTER(CrowdfundingTable[percent_funded],(CrowdfundingTable[subcategory]=$A22)*(CrowdfundingTable[outcome]=$D$2))),2),"")} | E22: {=IFERROR(ROUND(MEDIAN(_xlfn._xlws.FILTER(CrowdfundingTable[percent_funded],(CrowdfundingTable[subcategory]=$A22)*(CrowdfundingTable[outcome]=$E$2))),2),"")} -> 2.13 | F22: {=IFERROR(ROUND(MEDIAN(_xlfn._xlws.FILTER(CrowdfundingTable[percent_funded],CrowdfundingTable[subcategory]=$A22)),2),"")} -> 1.25
A23: world music | B23: {=IFERROR(ROUND(MEDIAN(_xlfn._xlws.FILTER(CrowdfundingTable[percent_funded],(CrowdfundingTable[subcategory]=$A23)*(CrowdfundingTable[outcome]=$B$2))),2),"")} | C23: {=IFERROR(ROUND(MEDIAN(_xlfn._xlws.FILTER(CrowdfundingTable[percent_funded],(CrowdfundingTable[subcategory]=$A23)*(CrowdfundingTable[outcome]=$C$2))),2),"")} | D23: {=IFERROR(ROUND(MEDIAN(_xlfn._xlws.FILTER(CrowdfundingTable[percent_funded],(CrowdfundingTable[subcategory]=$A23)*(CrowdfundingTable[outcome]=$D$2))),2),"")} | E23: {=IFERROR(ROUND(MEDIAN(_xlfn._xlws.FILTER(CrowdfundingTable[percent_funded],(CrowdfundingTable[subcategory]=$A23)*(CrowdfundingTable[outcome]=$E$2))),2),"")} -> 1.76 | F23: {=IFERROR(ROUND(MEDIAN(_xlfn._xlws.FILTER(CrowdfundingTable[percent_funded],CrowdfundingTable[subcategory]=$A23)),2),"")} -> 1.76
A24: photography | B24: {=IFERROR(ROUND(MEDIAN(_xlfn._xlws.FILTER(CrowdfundingTable[percent_funded],(CrowdfundingTable[primary_category]=$A24)*(CrowdfundingTable[outcome]=$B$2))),2),"")} -> 0.6 | C24: {=IFERROR(ROUND(MEDIAN(_xlfn._xlws.FILTER(CrowdfundingTable[percent_funded],(CrowdfundingTable[primary_category]=$A24)*(CrowdfundingTable[outcome]=$C$2))),2),"")} -> 0.36 | D24: {=IFERROR(ROUND(MEDIAN(_xlfn._xlws.FILTER(CrowdfundingTable[percent_funded],(CrowdfundingTable[primary_category]=$A24)*(CrowdfundingTable[outcome]=$D$2))),2),"")} -> 0.01 | E24: {=IFERROR(ROUND(MEDIAN(_xlfn._xlws.FILTER(CrowdfundingTable[percent_funded],(CrowdfundingTable[primary_category]=$A24)*(CrowdfundingTable[outcome]=$E$2))),2),"")} -> 2.55 | F24: {=IFERROR(ROUND(MEDIAN(_xlfn._xlws.FILTER(CrowdfundingTable[percent_funded],CrowdfundingTable[primary_category]=$A24)),2),"")} -> 1.44
A25: photography books | B25: {=IFERROR(ROUND(MEDIAN(_xlfn._xlws.FILTER(CrowdfundingTable[percent_funded],(CrowdfundingTable[subcategory]=$A25)*(CrowdfundingTable[outcome]=$B$2))),2),"")} -> 0.6 | C25: {=IFERROR(ROUND(MEDIAN(_xlfn._xlws.FILTER(CrowdfundingTable[percent_funded],(CrowdfundingTable[subcategory]=$A25)*(CrowdfundingTable[outcome]=$C$2))),2),"")} -> 0.36 | D25: {=IFERROR(ROUND(MEDIAN(_xlfn._xlws.FILTER(CrowdfundingTable[percent_funded],(CrowdfundingTable[subcategory]=$A25)*(CrowdfundingTable[outcome]=$D$2))),2),"")} -> 0.01 | E25: {=IFERROR(ROUND(MEDIAN(_xlfn._xlws.FILTER(CrowdfundingTable[percent_funded],(CrowdfundingTable[subcategory]=$A25)*(CrowdfundingTable[outcome]=$E$2))),2),"")} -> 2.55 | F25: {=IFERROR(ROUND(MEDIAN(_xlfn._xlws.FILTER(CrowdfundingTable[percent_funded],CrowdfundingTable[subcategory]=$A25)),2),"")} -> 1.44
A26: publishing | B26: {=IFERROR(ROUND(MEDIAN(_xlfn._xlws.FILTER(CrowdfundingTable[percent_funded],(CrowdfundingTable[primary_category]=$A26)*(CrowdfundingTable[outcome]=$B$2))),2),"")} -> 0.36 | C26: {=IFERROR(ROUND(MEDIAN(_xlfn._xlws.FILTER(CrowdfundingTable[percent_funded],(CrowdfundingTable[primary_category]=$A26)*(CrowdfundingTable[outcome]=$C$2))),2),"")} -> 0.42 | D26: {=IFERROR(ROUND(MEDIAN(_xlfn._xlws.FILTER(CrowdfundingTable[percent_funded],(CrowdfundingTable[primary_category]=$A26)*(CrowdfundingTable[outcome]=$D$2))),2),"")} -> 0.02 | E26: {=IFERROR(ROUND(MEDIAN(_xlfn._xlws.FILTER(CrowdfundingTable[percent_funded],(CrowdfundingTable[primary_category]=$A26)*(CrowdfundingTable[outcome]=$E$2))),2),"")} -> 2.28 | F26: {=IFERROR(ROUND(MEDIAN(_xlfn._xlws.FILTER(CrowdfundingTable[percent_funded],CrowdfundingTable[primary_category]=$A26)),2),"")} -> 1.26
A27: fiction | B27: {=IFERROR(ROUND(MEDIAN(_xlfn._xlws.FILTER(CrowdfundingTable[percent_funded],(CrowdfundingTable[subcategory]=$A27)*(CrowdfundingTable[outcome]=$B$2))),2),"")} -> 0.39 | C27: {=IFERROR(ROUND(MEDIAN(_xlfn._xlws.FILTER(CrowdfundingTable[percent_funded],(CrowdfundingTable[subcategory]=$A27)*(CrowdfundingTable[outcome]=$C$2))),2),"")} -> 0.64 | D27: {=IFERROR(ROUND(MEDIAN(_xlfn._xlws.FILTER(CrowdfundingTable[percent_funded],(CrowdfundingTable[subcategory]=$A27)*(CrowdfundingTable[outcome]=$D$2))),2),"")} | E27: {=IFERROR(ROUND(MEDIAN(_xlfn._xlws.FILTER(CrowdfundingTable[percent_funded],(CrowdfundingTable[subcategory]=$A27)*(CrowdfundingTable[outcome]=$E$2))),2),"")} -> 1.5 | F27: {=IFERROR(ROUND(MEDIAN(_xlfn._xlws.FILTER(CrowdfundingTable[percent_funded],CrowdfundingTable[subcategory]=$A27)),2),"")} -> 1.1
A28: nonfiction | B28: {=IFERROR(ROUND(MEDIAN(_xlfn._xlws.FILTER(CrowdfundingTable[percent_funded],(CrowdfundingTable[subcategory]=$A28)*(CrowdfundingTable[outcome]=$B$2))),2),"")} -> 0.33 | C28: {=IFERROR(ROUND(MEDIAN(_xlfn._xlws.FILTER(CrowdfundingTable[percent_funded],(CrowdfundingTable[subcategory]=$A28)*(CrowdfundingTable[outcome]=$C$2))),2),"")} -> 0.41 | D28: {=IFERROR(ROUND(MEDIAN(_xlfn._xlws.FILTER(CrowdfundingTable[percent_funded],(CrowdfundingTable[subcategory]=$A28)*(CrowdfundingTable[outcome]=$D$2))),2),"")} -> 0.02 | E28: {=IFERROR(ROUND(MEDIAN(_xlfn._xlws.FILTER(CrowdfundingTable[percent_funded],(CrowdfundingTable[subcategory]=$A28)*(CrowdfundingTable[outcome]=$E$2))),2),"")} -> 2.32 | F28: {=IFERROR(ROUND(MEDIAN(_xlfn._xlws.FILTER(CrowdfundingTable[percent_funded],CrowdfundingTable[subcategory]=$A28)),2),"")} -> 1.46
A29: radio & podcasts | B29: {=IFERROR(ROUND(MEDIAN(_xlfn._xlws.FILTER(CrowdfundingTable[percent_funded],(CrowdfundingTable[subcategory]=$A29)*(CrowdfundingTable[outcome]=$B$2))),2),"")} | C29: {=IFERROR(ROUND(MEDIAN(_xlfn._xlws.FILTER(CrowdfundingTable[percent_funded],(CrowdfundingTable[subcategory]=$A29)*(CrowdfundingTable[outcome]=$C$2))),2),"")} -> 0.33 | D29: {=IFERROR(ROUND(MEDIAN(_xlfn._xlws.FILTER(CrowdfundingTable[percent_funded],(CrowdfundingTable[subcategory]=$A29)*(CrowdfundingTable[outcome]=$D$2))),2),"")} | E29: {=IFERROR(ROUND(MEDIAN(_xlfn._xlws.FILTER(CrowdfundingTable[percent_funded],(CrowdfundingTable[subcategory]=$A29)*(CrowdfundingTable[outcome]=$E$2))),2),"")} -> 1.74 | F29: {=IFERROR(ROUND(MEDIAN(_xlfn._xlws.FILTER(CrowdfundingTable[percent_funded],CrowdfundingTable[subcategory]=$A29)),2),"")} -> 1.01
A30: translations | B30: {=IFERROR(ROUND(MEDIAN(_xlfn._xlws.FILTER(CrowdfundingTable[percent_funded],(CrowdfundingTable[subcategory]=$A30)*(CrowdfundingTable[outcome]=$B$2))),2),"")} | C30: {=IFERROR(ROUND(MEDIAN(_xlfn._xlws.FILTER(CrowdfundingTable[percent_funded],(CrowdfundingTable[subcategory]=$A30)*(CrowdfundingTable[outcome]=$C$2))),2),"")} -> 0.41 | D30: {=IFERROR(ROUND(MEDIAN(_xlfn._xlws.FILTER(CrowdfundingTable[percent_funded],(CrowdfundingTable[subcategory]=$A30)*(CrowdfundingTable[outcome]=$D$2))),2),"")} | E30: {=IFERROR(ROUND(MEDIAN(_xlfn._xlws.FILTER(CrowdfundingTable[percent_funded],(CrowdfundingTable[subcategory]=$A30)*(CrowdfundingTable[outcome]=$E$2))),2),"")} -> 2.41 | F30: {=IFERROR(ROUND(MEDIAN(_xlfn._xlws.FILTER(CrowdfundingTable[percent_funded],CrowdfundingTable[subcategory]=$A30)),2),"")} -> 1.58
A31: technology | B31: {=IFERROR(ROUND(MEDIAN(_xlfn._xlws.FILTER(CrowdfundingTable[percent_funded],(CrowdfundingTable[primary_category]=$A31)*(CrowdfundingTable[outcome]=$B$2))),2),"")} -> 0.64 | C31: {=IFERROR(ROUND(MEDIAN(_xlfn._xlws.FILTER(CrowdfundingTable[percent_funded],(CrowdfundingTable[primary_category]=$A31)*(CrowdfundingTable[outcome]=$C$2))),2),"")} -> 0.62 | D31: {=IFERROR(ROUND(MEDIAN(_xlfn._xlws.FILTER(CrowdfundingTable[percent_funded],(CrowdfundingTable[primary_category]=$A31)*(CrowdfundingTable[outcome]=$D$2))),2),"")} -> 0.61 | E31: {=IFERROR(ROUND(MEDIAN(_xlfn._xlws.FILTER(CrowdfundingTable[percent_funded],(CrowdfundingTable[primary_category]=$A31)*(CrowdfundingTable[outcome]=$E$2))),2),"")} -> 1.99 | F31: {=IFERROR(ROUND(MEDIAN(_xlfn._xlws.FILTER(CrowdfundingTable[percent_funded],CrowdfundingTable[primary_category]=$A31)),2),"")} -> 1.32
A32: wearables | B32: {=IFERROR(ROUND(MEDIAN(_xlfn._xlws.FILTER(CrowdfundingTable[percent_funded],(CrowdfundingTable[subcategory]=$A32)*(CrowdfundingTable[outcome]=$B$2))),2),"")} | C32: {=IFERROR(ROUND(MEDIAN(_xlfn._xlws.FILTER(CrowdfundingTable[percent_funded],(CrowdfundingTable[subcategory]=$A32)*(CrowdfundingTable[outcome]=$C$2))),2),"")} -> 0.59 | D32: {=IFERROR(ROUND(MEDIAN(_xlfn._xlws.FILTER(CrowdfundingTable[percent_funded],(CrowdfundingTable[subcategory]=$A32)*(CrowdfundingTable[outcome]=$D$2))),2),"")} -> 0.59 | E32: {=IFERROR(ROUND(MEDIAN(_xlfn._xlws.FILTER(CrowdfundingTable[percent_funded],(CrowdfundingTable[subcategory]=$A32)*(CrowdfundingTable[outcome]=$E$2))),2),"")} -> 2.21 | F32: {=IFERROR(ROUND(MEDIAN(_xlfn._xlws.FILTER(CrowdfundingTable[percent_funded],CrowdfundingTable[subcategory]=$A32)),2),"")} -> 1.44
A33: web | B33: {=IFERROR(ROUND(MEDIAN(_xlfn._xlws.FILTER(CrowdfundingTable[percent_funded],(CrowdfundingTable[subcategory]=$A33)*(CrowdfundingTable[outcome]=$B$2))),2),"")} -> 0.64 | C33: {=IFERROR(ROUND(MEDIAN(_xlfn._xlws.FILTER(CrowdfundingTable[percent_funded],(CrowdfundingTable[subcategory]=$A33)*(CrowdfundingTable[outcome]=$C$2))),2),"")} -> 0.63 | D33: {=IFERROR(ROUND(MEDIAN(_xlfn._xlws.FILTER(CrowdfundingTable[percent_funded],(CrowdfundingTable[subcategory]=$A33)*(CrowdfundingTable[outcome]=$D$2))),2),"")} -> 0.62 | E33: {=IFERROR(ROUND(MEDIAN(_xlfn._xlws.FILTER(CrowdfundingTable[percent_funded],(CrowdfundingTable[subcategory]=$A33)*(CrowdfundingTable[outcome]=$E$2))),2),"")} -> 1.88 | F33: {=IFERROR(ROUND(MEDIAN(_xlfn._xlws.FILTER(CrowdfundingTable[percent_funded],CrowdfundingTable[subcategory]=$A33)),2),"")} -> 1.28
A34: theater | B34: {=IFERROR(ROUND(MEDIAN(_xlfn._xlws.FILTER(CrowdfundingTable[percent_funded],(CrowdfundingTable[primary_category]=$A34)*(CrowdfundingTable[outcome]=$B$2))),2),"")} -> 0.48 | C34: {=IFERROR(ROUND(MEDIAN(_xlfn._xlws.FILTER(CrowdfundingTable[percent_funded],(CrowdfundingTable[primary_category]=$A34)*(CrowdfundingTable[outcome]=$C$2))),2),"")} -> 0.51 | D34: {=IFERROR(ROUND(MEDIAN(_xlfn._xlws.FILTER(CrowdfundingTable[percent_funded],(CrowdfundingTable[primary_category]=$A34)*(CrowdfundingTable[outcome]=$D$2))),2),"")} -> 0.31 | E34: {=IFERROR(ROUND(MEDIAN(_xlfn._xlws.FILTER(CrowdfundingTable[percent_funded],(CrowdfundingTable[primary_category]=$A34)*(CrowdfundingTable[outcome]=$E$2))),2),"")} -> 2.02 | F34: {=IFERROR(ROUND(MEDIAN(_xlfn._xlws.FILTER(CrowdfundingTable[percent_funded],CrowdfundingTable[primary_category]=$A34)),2),"")} -> 1.13
A35: plays | B35: {=IFERROR(ROUND(MEDIAN(_xlfn._xlws.FILTER(CrowdfundingTable[percent_funded],(CrowdfundingTable[subcategory]=$A35)*(CrowdfundingTable[outcome]=$B$2))),2),"")} -> 0.48 | C35: {=IFERROR(ROUND(MEDIAN(_xlfn._xlws.FILTER(CrowdfundingTable[percent_funded],(CrowdfundingTable[subcategory]=$A35)*(CrowdfundingTable[outcome]=$C$2))),2),"")} -> 0.51 | D35: {=IFERROR(ROUND(MEDIAN(_xlfn._xlws.FILTER(CrowdfundingTable[percent_funded],(CrowdfundingTable[subcategory]=$A35)*(CrowdfundingTable[outcome]=$D$2))),2),"")} -> 0.31 | E35: {=IFERROR(ROUND(MEDIAN(_xlfn._xlws.FILTER(CrowdfundingTable[percent_funded],(CrowdfundingTable[subcategory]=$A35)*(CrowdfundingTable[outcome]=$E$2))),2),"")} -> 2.02 | F35: {=IFERROR(ROUND(MEDIAN(_xlfn._xlws.FILTER(CrowdfundingTable[percent_funded],CrowdfundingTable[subcategory]=$A35)),2),"")} -> 1.13
A36: Grand Total | B36: {=IFERROR(ROUND(MEDIAN(_xlfn._xlws.FILTER(CrowdfundingTable[percent_funded],CrowdfundingTable[outcome]=$B$2)),2),"")} -> 0.43 | C36: {=IFERROR(ROUND(MEDIAN(_xlfn._xlws.FILTER(CrowdfundingTable[percent_funded],CrowdfundingTable[outcome]=$C$2)),2),"")} -> 0.51 | D36: {=IFERROR(ROUND(MEDIAN(_xlfn._xlws.FILTER(CrowdfundingTable[percent_funded],CrowdfundingTable[outcome]=$D$2)),2),"")} -> 0.5 | E36: {=IFERROR(ROUND(MEDIAN(_xlfn._xlws.FILTER(CrowdfundingTable[percent_funded],CrowdfundingTable[outcome]=$E$2)),2),"")} -> 2.12 | F36: =IFERROR(ROUND(MEDIAN(CrowdfundingTable[percent_funded]),2),"") -> 1.22

Sheet Outcomes vs. Weekdays
A1: country | B1: (All) | I1: country | J1: (All)
A2: Years | B2: (All) | I2: Years | J2: (All)
A4: Count of outcome | B4: Column Labels | I4: Count of outcome | J4: Column Labels | N4: Confidence Interval
A5: Row Labels | B5: canceled | C5: failed | D5: successful | E5: Grand Total | I5: Row Labels | J5: canceled | K5: failed | L5: successful | M5: Grand Total | N5: (successful)
A6: Sun | B6: 8 | C6: 47 | D6: 78 | E6: 133 | I6: Sun | J6: 0.060150376 | K6: 0.35338346 | L6: 0.58646617 | M6: 1 | N6: =GETPIVOTDATA("outcome",$I$4,"outcome","successful","weekday_created","Sun")-1.96*GETPIVOTDATA("outcome",$I$4,"outcome","successful","weekday_created","Sun")*(1-GETPIVOTDATA("outcome",$I$4,"outcome","successful","weekday_created","Sun"))/GETPIVOTDATA("outcome",$A$4,"weekday_created","Sun") -> 0.58289213 | O6: =GETPIVOTDATA("outcome",$I$4,"outcome","successful","weekday_created","Sun")+1.96*GETPIVOTDATA("outcome",$I$4,"outcome","successful","weekday_created","Sun")*(1-GETPIVOTDATA("outcome",$I$4,"outcome","successful","weekday_created","Sun"))/GETPIVOTDATA("outcome",$A$4,"weekday_created","Sun") -> 0.5900402
A7: Mon | B7: 6 | C7: 46 | D7: 100 | E7: 152 | I7: Mon | J7: 0.039473684 | K7: 0.30263158 | L7: 0.65789474 | M7: 1 | N7: =GETPIVOTDATA("outcome",$I$4,"outcome","successful","weekday_created","Mon")-1.96*GETPIVOTDATA("outcome",$I$4,"outcome","successful","weekday_created","Mon")*(1-GETPIVOTDATA("outcome",$I$4,"outcome","successful","weekday_created","Mon"))/GETPIVOTDATA("outcome",$A$4,"weekday_created","Mon") -> 0.65499253 | O7: =GETPIVOTDATA("outcome",$I$4,"outcome","successful","weekday_created","Mon")+1.96*GETPIVOTDATA("outcome",$I$4,"outcome","successful","weekday_created","Mon")*(1-GETPIVOTDATA("outcome",$I$4,"outcome","successful","weekday_created","Mon"))/GETPIVOTDATA("outcome",$A$4,"weekday_created","Mon") -> 0.66079695
A8: Tue | B8: 7 | C8: 58 | D8: 84 | E8: 149 | I8: Tue | J8: 0.046979866 | K8: 0.38926174 | L8: 0.56375839 | M8: 1 | N8: =GETPIVOTDATA("outcome",$I$4,"outcome","successful","weekday_created","Tue")-1.96*GETPIVOTDATA("outcome",$I$4,"outcome","successful","weekday_created","Tue")*(1-GETPIVOTDATA("outcome",$I$4,"outcome","successful","weekday_created","Tue"))/GETPIVOTDATA("outcome",$A$4,"weekday_created","Tue") -> 0.56052327 | O8: =GETPIVOTDATA("outcome",$I$4,"outcome","successful","weekday_created","Tue")+1.96*GETPIVOTDATA("outcome",$I$4,"outcome","successful","weekday_created","Tue")*(1-GETPIVOTDATA("outcome",$I$4,"outcome","successful","weekday_created","Tue"))/GETPIVOTDATA("outcome",$A$4,"weekday_created","Tue") -> 0.56699351
A9: Wed | B9: 9 | C9: 51 | D9: 76 | E9: 136 | I9: Wed | J9: 0.066176471 | K9: 0.375 | L9: 0.55882353 | M9: 1 | N9: =GETPIVOTDATA("outcome",$I$4,"outcome","successful","weekday_created","Wed")-1.96*GETPIVOTDATA("outcome",$I$4,"outcome","successful","weekday_created","Wed")*(1-GETPIVOTDATA("outcome",$I$4,"outcome","successful","weekday_created","Wed"))/GETPIVOTDATA("outcome",$A$4,"weekday_created","Wed") -> 0.55527046 | O9: =GETPIVOTDATA("outcome",$I$4,"outcome","successful","weekday_created","Wed")+1.96*GETPIVOTDATA("outcome",$I$4,"outcome","successful","weekday_created","Wed")*(1-GETPIVOTDATA("outcome",$I$4,"outcome","successful","weekday_created","Wed"))/GETPIVOTDATA("outcome",$A$4,"weekday_created","Wed") -> 0.5623766
A10: Thu | B10: 11 | C10: 53 | D10: 78 | E10: 142 | I10: Thu | J10: 0.077464789 | K10: 0.37323944 | L10: 0.54929577 | M10: 1 | N10: =GETPIVOTDATA("outcome",$I$4,"outcome","successful","weekday_created","Thu")-1.96*GETPIVOTDATA("outcome",$I$4,"outcome","successful","weekday_created","Thu")*(1-GETPIVOTDATA("outcome",$I$4,"outcome","successful","weekday_created","Thu"))/GETPIVOTDATA("outcome",$A$4,"weekday_created","Thu") -> 0.54587861 | O10: =GETPIVOTDATA("outcome",$I$4,"outcome","successful","weekday_created","Thu")+1.96*GETPIVOTDATA("outcome",$I$4,"outcome","successful","weekday_created","Thu")*(1-GETPIVOTDATA("outcome",$I$4,"outcome","successful","weekday_created","Thu"))/GETPIVOTDATA("outcome",$A$4,"weekday_created","Thu") -> 0.55271294
A11: Fri | B11: 8 | C11: 64 | D11: 75 | E11: 147 | I11: Fri | J11: 0.054421769 | K11: 0.43537415 | L11: 0.51020408 | M11: 1 | N11: =GETPIVOTDATA("outcome",$I$4,"outcome","successful","weekday_created","Fri")-1.96*GETPIVOTDATA("outcome",$I$4,"outcome","successful","weekday_created","Fri")*(1-GETPIVOTDATA("outcome",$I$4,"outcome","successful","weekday_created","Fri"))/GETPIVOTDATA("outcome",$A$4,"weekday_created","Fri") -> 0.50687214 | O11: =GETPIVOTDATA("outcome",$I$4,"outcome","successful","weekday_created","Fri")+1.96*GETPIVOTDATA("outcome",$I$4,"outcome","successful","weekday_created","Fri")*(1-GETPIVOTDATA("outcome",$I$4,"outcome","successful","weekday_created","Fri"))/GETPIVOTDATA("outcome",$A$4,"weekday_created","Fri") -> 0.51353603
A12: Sat | B12: 8 | C12: 45 | D12: 74 | E12: 127 | I12: Sat | J12: 0.062992126 | K12: 0.35433071 | L12: 0.58267717 | M12: 1 | N12: =GETPIVOTDATA("outcome",$I$4,"outcome","successful","weekday_created","Sat")-1.96*GETPIVOTDATA("outcome",$I$4,"outcome","successful","weekday_created","Sat")*(1-GETPIVOTDATA("outcome",$I$4,"outcome","successful","weekday_created","Sat"))/GETPIVOTDATA("outcome",$A$4,"weekday_created","Sat") -> 0.57892439 | O12: =GETPIVOTDATA("outcome",$I$4,"outcome","successful","weekday_created","Sat")+1.96*GETPIVOTDATA("outcome",$I$4,"outcome","successful","weekday_created","Sat")*(1-GETPIVOTDATA("outcome",$I$4,"outcome","successful","weekday_created","Sat"))/GETPIVOTDATA("outcome",$A$4,"weekday_created","Sat") -> 0.58642994
A13: Grand Total | B13: 57 | C13: 364 | D13: 565 | E13: 986 | I13: Grand Total | J13: 0.057809331 | K13: 0.36916836 | L13: 0.57302231 | M13: 1 | N13: =GETPIVOTDATA("outcome",$I$4,"outcome","successful")-1.96*GETPIVOTDATA("outcome",$I$4,"outcome","successful")*(1-GETPIVOTDATA("outcome",$I$4,"outcome","successful"))/GETPIVOTDATA("outcome",$A$4) -> 0.57253595 | O13: =GETPIVOTDATA("outcome",$I$4,"outcome","successful")+1.96*GETPIVOTDATA("outcome",$I$4,"outcome","successful")*(1-GETPIVOTDATA("outcome",$I$4,"outcome","successful"))/GETPIVOTDATA("outcome",$A$4) -> 0.57350867

Sheet Outcomes vs. Months
A1: country | B1: (All) | J1: country | K1: (All)
A2: Years | B2: (All) | J2: Years | K2: (All)
A4: Count of outcome | B4: Column Labels | J4: Count of outcome | K4: Column Labels | O4: Confidence Interval
A5: Row Labels | B5: canceled | C5: failed | D5: successful | E5: Grand Total | J5: Row Labels | K5: canceled | L5: failed | M5: successful | N5: Grand Total | O5: (successful)
A6: Jan | B6: 6 | C6: 36 | D6: 49 | E6: 91 | J6: Jan | K6: 0.065934066 | L6: 0.3956044 | M6: 0.53846154 | N6: 1 | O6: =GETPIVOTDATA("outcome",$J$4,"outcome","successful","Date Created Conversion",1)-1.96*GETPIVOTDATA("outcome",$J$4,"outcome","successful","Date Created Conversion",1)*(1-GETPIVOTDATA("outcome",$J$4,"outcome","successful","Date Created Conversion",1))/GETPIVOTDATA("outcome",$A$4,"Date Created Conversion",1) -> 0.53310878 | P6: =GETPIVOTDATA("outcome",$J$4,"outcome","successful","Date Created Conversion",1)+1.96*GETPIVOTDATA("outcome",$J$4,"outcome","successful","Date Created Conversion",1)*(1-GETPIVOTDATA("outcome",$J$4,"outcome","successful","Date Created Conversion",1))/GETPIVOTDATA("outcome",$A$4,"Date Created Conversion",1) -> 0.54381429
A7: Feb | B7: 7 | C7: 28 | D7: 44 | E7: 79 | J7: Feb | K7: 0.088607595 | L7: 0.35443038 | M7: 0.55696203 | N7: 1 | O7: =GETPIVOTDATA("outcome",$J$4,"outcome","successful","Date Created Conversion",2)-1.96*GETPIVOTDATA("outcome",$J$4,"outcome","successful","Date Created Conversion",2)*(1-GETPIVOTDATA("outcome",$J$4,"outcome","successful","Date Created Conversion",2))/GETPIVOTDATA("outcome",$A$4,"Date Created Conversion",2) -> 0.55083999 | P7: =GETPIVOTDATA("outcome",$J$4,"outcome","successful","Date Created Conversion",2)+1.96*GETPIVOTDATA("outcome",$J$4,"outcome","successful","Date Created Conversion",2)*(1-GETPIVOTDATA("outcome",$J$4,"outcome","successful","Date Created Conversion",2))/GETPIVOTDATA("outcome",$A$4,"Date Created Conversion",2) -> 0.56308406
A8: Mar | B8: 4 | C8: 33 | D8: 49 | E8: 86 | J8: Mar | K8: 0.046511628 | L8: 0.38372093 | M8: 0.56976744 | N8: 1 | O8: =GETPIVOTDATA("outcome",$J$4,"outcome","successful","Date Created Conversion",3)-1.96*GETPIVOTDATA("outcome",$J$4,"outcome","successful","Date Created Conversion",3)*(1-GETPIVOTDATA("outcome",$J$4,"outcome","successful","Date Created Conversion",3))/GETPIVOTDATA("outcome",$A$4,"Date Created Conversion",3) -> 0.5641807 | P8: =GETPIVOTDATA("outcome",$J$4,"outcome","successful","Date Created Conversion",3)+1.96*GETPIVOTDATA("outcome",$J$4,"outcome","successful","Date Created Conversion",3)*(1-GETPIVOTDATA("outcome",$J$4,"outcome","successful","Date Created Conversion",3))/GETPIVOTDATA("outcome",$A$4,"Date Created Conversion",3) -> 0.57535418
A9: Apr | B9: 1 | C9: 30 | D9: 46 | E9: 77 | J9: Apr | K9: 0.012987013 | L9: 0.38961039 | M9: 0.5974026 | N9: 1 | O9: =GETPIVOTDATA("outcome",$J$4,"outcome","successful","Date Created Conversion",4)-1.96*GETPIVOTDATA("outcome",$J$4,"outcome","successful","Date Created Conversion",4)*(1-GETPIVOTDATA("outcome",$J$4,"outcome","successful","Date Created Conversion",4))/GETPIVOTDATA("outcome",$A$4,"Date Created Conversion",4) -> 0.59128046 | P9: =GETPIVOTDATA("outcome",$J$4,"outcome","successful","Date Created Conversion",4)+1.96*GETPIVOTDATA("outcome",$J$4,"outcome","successful","Date Created Conversion",4)*(1-GETPIVOTDATA("outcome",$J$4,"outcome","successful","Date Created Conversion",4))/GETPIVOTDATA("outcome",$A$4,"Date Created Conversion",4) -> 0.60352474
A10: May | B10: 3 | C10: 35 | D10: 46 | E10: 84 | J10: May | K10: 0.035714286 | L10: 0.41666667 | M10: 0.54761905 | N10: 1 | O10: =GETPIVOTDATA("outcome",$J$4,"outcome","successful","Date Created Conversion",5)-1.96*GETPIVOTDATA("outcome",$J$4,"outcome","successful","Date Created Conversion",5)*(1-GETPIVOTDATA("outcome",$J$4,"outcome","successful","Date Created Conversion",5))/GETPIVOTDATA("outcome",$A$4,"Date Created Conversion",5) -> 0.54183862 | P10: =GETPIVOTDATA("outcome",$J$4,"outcome","successful","Date Created Conversion",5)+1.96*GETPIVOTDATA("outcome",$J$4,"outcome","successful","Date Created Conversion",5)*(1-GETPIVOTDATA("outcome",$J$4,"outcome","successful","Date Created Conversion",5))/GETPIVOTDATA("outcome",$A$4,"Date Created Conversion",5) -> 0.55339947
A11: Jun | B11: 3 | C11: 28 | D11: 55 | E11: 86 | J11: Jun | K11: 0.034883721 | L11: 0.3255814 | M11: 0.63953488 | N11: 1 | O11: =GETPIVOTDATA("outcome",$J$4,"outcome","successful","Date Created Conversion",6)-1.96*GETPIVOTDATA("outcome",$J$4,"outcome","successful","Date Created Conversion",6)*(1-GETPIVOTDATA("outcome",$J$4,"outcome","successful","Date Created Conversion",6))/GETPIVOTDATA("outcome",$A$4,"Date Created Conversion",6) -> 0.63428094 | P11: =GETPIVOTDATA("outcome",$J$4,"outcome","successful","Date Created Conversion",6)+1.96*GETPIVOTDATA("outcome",$J$4,"outcome","successful","Date Created Conversion",6)*(1-GETPIVOTDATA("outcome",$J$4,"outcome","successful","Date Created Conversion",6))/GETPIVOTDATA("outcome",$A$4,"Date Created Conversion",6) -> 0.64478882
A12: Jul | B12: 4 | C12: 31 | D12: 58 | E12: 93 | J12: Jul | K12: 0.043010753 | L12: 0.33333333 | M12: 0.62365591 | N12: 1 | O12: =GETPIVOTDATA("outcome",$J$4,"outcome","successful","Date Created Conversion",7)-1.96*GETPIVOTDATA("outcome",$J$4,"outcome","successful","Date Created Conversion",7)*(1-GETPIVOTDATA("outcome",$J$4,"outcome","successful","Date Created Conversion",7))/GETPIVOTDATA("outcome",$A$4,"Date Created Conversion",7) -> 0.61870935 | P12: =GETPIVOTDATA("outcome",$J$4,"outcome","successful","Date Created Conversion",7)+1.96*GETPIVOTDATA("outcome",$J$4,"outcome","successful","Date Created Conversion",7)*(1-GETPIVOTDATA("outcome",$J$4,"outcome","successful","Date Created Conversion",7))/GETPIVOTDATA("outcome",$A$4,"Date Created Conversion",7) -> 0.62860247
A13: Aug | B13: 8 | C13: 35 | D13: 41 | E13: 84 | J13: Aug | K13: 0.095238095 | L13: 0.41666667 | M13: 0.48809524 | N13: 1 | O13: =GETPIVOTDATA("outcome",$J$4,"outcome","successful","Date Created Conversion",8)-1.96*GETPIVOTDATA("outcome",$J$4,"outcome","successful","Date Created Conversion",8)*(1-GETPIVOTDATA("outcome",$J$4,"outcome","successful","Date Created Conversion",8))/GETPIVOTDATA("outcome",$A$4,"Date Created Conversion",8) -> 0.48226521 | P13: =GETPIVOTDATA("outcome",$J$4,"outcome","successful","Date Created Conversion",8)+1.96*GETPIVOTDATA("outcome",$J$4,"outcome","successful","Date Created Conversion",8)*(1-GETPIVOTDATA("outcome",$J$4,"outcome","successful","Date Created Conversion",8))/GETPIVOTDATA("outcome",$A$4,"Date Created Conversion",8) -> 0.49392526
A14: Sep | B14: 5 | C14: 23 | D14: 45 | E14: 73 | J14: Sep | K14: 0.068493151 | L14: 0.31506849 | M14: 0.61643836 | N14: 1 | O14: =GETPIVOTDATA("outcome",$J$4,"outcome","successful","Date Created Conversion",9)-1.96*GETPIVOTDATA("outcome",$J$4,"outcome","successful","Date Created Conversion",9)*(1-GETPIVOTDATA("outcome",$J$4,"outcome","successful","Date Created Conversion",9))/GETPIVOTDATA("outcome",$A$4,"Date Created Conversion",9) -> 0.61009005 | P14: =GETPIVOTDATA("outcome",$J$4,"outcome","successful","Date Created Conversion",9)+1.96*GETPIVOTDATA("outcome",$J$4,"outcome","successful","Date Created Conversion",9)*(1-GETPIVOTDATA("outcome",$J$4,"outcome","successful","Date Created Conversion",9))/GETPIVOTDATA("outcome",$A$4,"Date Created Conversion",9) -> 0.62278666
A15: Oct | B15: 6 | C15: 26 | D15: 45 | E15: 77 | J15: Oct | K15: 0.077922078 | L15: 0.33766234 | M15: 0.58441558 | N15: 1 | O15: =GETPIVOTDATA("outcome",$J$4,"outcome","successful","Date Created Conversion",10)-1.96*GETPIVOTDATA("outcome",$J$4,"outcome","successful","Date Created Conversion",10)*(1-GETPIVOTDATA("outcome",$J$4,"outcome","successful","Date Created Conversion",10))/GETPIVOTDATA("outcome",$A$4,"Date Created Conversion",10) -> 0.57823334 | P15: =GETPIVOTDATA("outcome",$J$4,"outcome","successful","Date Created Conversion",10)+1.96*GETPIVOTDATA("outcome",$J$4,"outcome","successful","Date Created Conversion",10)*(1-GETPIVOTDATA("outcome",$J$4,"outcome","successful","Date Created Conversion",10))/GETPIVOTDATA("outcome",$A$4,"Date Created Conversion",10) -> 0.59059783
A16: Nov | B16: 3 | C16: 27 | D16: 45 | E16: 75 | J16: Nov | K16: 0.04 | L16: 0.36 | M16: 0.6 | N16: 1 | O16: =GETPIVOTDATA("outcome",$J$4,"outcome","successful","Date Created Conversion",11)-1.96*GETPIVOTDATA("outcome",$J$4,"outcome","successful","Date Created Conversion",11)*(1-GETPIVOTDATA("outcome",$J$4,"outcome","successful","Date Created Conversion",11))/GETPIVOTDATA("outcome",$A$4,"Date Created Conversion",11) -> 0.593728 | P16: =GETPIVOTDATA("outcome",$J$4,"outcome","successful","Date Created Conversion",11)+1.96*GETPIVOTDATA("outcome",$J$4,"outcome","successful","Date Created Conversion",11)*(1-GETPIVOTDATA("outcome",$J$4,"outcome","successful","Date Created Conversion",11))/GETPIVOTDATA("outcome",$A$4,"Date Created Conversion",11) -> 0.606272
A17: Dec | B17: 7 | C17: 32 | D17: 42 | E17: 81 | J17: Dec | K17: 0.086419753 | L17: 0.39506173 | M17: 0.51851852 | N17: 1 | O17: =GETPIVOTDATA("outcome",$J$4,"outcome","successful","Date Created Conversion",12)-1.96*GETPIVOTDATA("outcome",$J$4,"outcome","successful","Date Created Conversion",12)*(1-GETPIVOTDATA("outcome",$J$4,"outcome","successful","Date Created Conversion",12))/GETPIVOTDATA("outcome",$A$4,"Date Created Conversion",12) -> 0.51247743 | P17: =GETPIVOTDATA("outcome",$J$4,"outcome","successful","Date Created Conversion",12)+1.96*GETPIVOTDATA("outcome",$J$4,"outcome","successful","Date Created Conversion",12)*(1-GETPIVOTDATA("outcome",$J$4,"outcome","successful","Date Created Conversion",12))/GETPIVOTDATA("outcome",$A$4,"Date Created Conversion",12) -> 0.5245596
